<mujoco model="humanoid">
  <compiler angle="radian" autolimits="true"/>
  <!-- each time step is 1/120 of a second -->
  <option viscosity="0.00002" integrator="implicitfast"/>
  <visual>
    <quality shadowsize="2048"/>
    <headlight ambient="0.4 0.4 0.4" diffuse="0.8 0.8 0.8" specular="0.1 0.1 0.1"/>
  </visual>
  <statistic extent="3" center="0 0 1"/>
  <default class="main">
    <joint limited="true" range="0 1.047" armature="0.01"/>
    <geom contype="7" conaffinity="7" condim="1" margin="0.001" rgba="0.8 0.6 0.4 1"/>
  </default>
  <asset>
    <texture type="skybox" builtin="gradient" rgb1="0.4 0.5 0.6" rgb2="0 0 0" width="100" height="600"/>
    <texture type="cube" name="texgeom" builtin="flat" mark="cross" rgb1="0.8 0.6 0.4" rgb2="0.8 0.6 0.4" markrgb="1 1 1" width="127" height="762"/>
    <texture type="2d" name="texplane" builtin="checker" rgb1="0 0 0" rgb2="0.8 0.8 0.8" width="100" height="100"/>
    <material name="MatPlane" texture="texplane" texrepeat="60 60" specular="1" shininess="1" reflectance="0.5"/>
    <material name="geom" texture="texgeom" texuniform="true"/>
    <mesh name="Pelvis" file="./geom/Pelvis.stl"/>
    <mesh name="L_Hip" file="./geom/L_Hip.stl"/>
    <mesh name="R_Hip" file="./geom/R_Hip.stl"/>
    <mesh name="Torso" file="./geom/Torso.stl"/>  <!-- Spine_1 -->
    <mesh name="L_Knee" file="./geom/L_Knee.stl"/>
    <mesh name="R_Knee" file="./geom/R_Knee.stl"/>
    <mesh name="Spine" file="./geom/Spine.stl"/>  <!-- Spine_2 -->
    <mesh name="L_Ankle" file="./geom/L_Ankle.stl"/>
    <mesh name="R_Ankle" file="./geom/R_Ankle.stl"/>
    <mesh name="Chest" file="./geom/Chest.stl"/>  <!-- Spine_3 -->
    <mesh name="L_Toe" file="./geom/L_Toe.stl"/>  <!-- L_Foot -->
    <mesh name="R_Toe" file="./geom/R_Toe.stl"/>  <!-- R_Foot -->
    <mesh name="Neck" file="./geom/Neck.stl"/>
    <mesh name="L_Thorax" file="./geom/L_Thorax.stl"/>  <!-- L_Collar -->
    <mesh name="R_Thorax" file="./geom/R_Thorax.stl"/>  <!-- R_Collar -->
    <mesh name="Head" file="./geom/Head.stl"/>
    <mesh name="L_Shoulder" file="./geom/L_Shoulder.stl"/>
    <mesh name="R_Shoulder" file="./geom/R_Shoulder.stl"/>
    <mesh name="L_Elbow" file="./geom/L_Elbow.stl"/>
    <mesh name="R_Elbow" file="./geom/R_Elbow.stl"/>
    <mesh name="L_Wrist" file="./geom/L_Wrist.stl"/>
    <mesh name="R_Wrist" file="./geom/R_Wrist.stl"/>
    <mesh name="L_Hand" file="./geom/L_Hand.stl"/>
    <mesh name="R_Hand" file="./geom/R_Hand.stl"/>
  </asset>
  <worldbody>
    <geom name="floor" size="100 100 0.2" type="plane" conaffinity="1" condim="3" material="MatPlane" rgba="0.8 0.9 0.8 1"/>
    <light pos="0 0 1.3" dir="0 0 -1" directional="true" cutoff="100" exponent="1" diffuse="1 1 1" specular="0.1 0.1 0.1"/>
    <body name="Pelvis" pos="-0.0018 -0.90233 2.0282" quat="0.5 0.5 0.5 0.5" gravcomp="0">
      <joint name="Pelvis" type="free" pos="0 0 0"/>
      <geom pos="0.0018 0.2233 0.0282" type="mesh" contype="1" conaffinity="1" mesh="Pelvis"/>
      <body name="L_Hip" pos="0.0695 -0.0914 -0.0068" gravcomp="0">
        <joint name="L_Hip" type="ball" pos="0 0 0" limited="true"/>
        <geom pos="-0.0677 0.3147 -0.0214" type="mesh" contype="1" conaffinity="1" mesh="L_Hip"/>
        <body name="L_Knee" pos="0.0343 -0.3752 -0.0045" gravcomp="0">
          <joint name="L_Knee" type="ball" pos="0 0 0"/>
          <geom pos="-0.102 0.6899 -0.0169" type="mesh" contype="1" conaffinity="1" mesh="L_Knee"/>
          <body name="L_Ankle" pos="-0.0136 -0.398 -0.0437" gravcomp="0">
            <joint name="L_Ankle" type="ball" pos="0 0 0"/>
            <geom pos="-0.0884 1.0879 0.0268" type="mesh" contype="1" conaffinity="1" mesh="L_Ankle"/>
            <body name="L_Toe" pos="0.0264 -0.0558 0.1193" gravcomp="0">
              <joint name="L_Toe" type="ball" pos="0 0 0"/>
              <geom pos="-0.1148 1.1437 -0.0925" type="mesh" contype="1" conaffinity="1" mesh="L_Toe"/>
            </body>
          </body>
        </body>
      </body>
      <body name="R_Hip" pos="-0.0677 -0.0906 -0.0043" gravcomp="0">
        <joint name="R_Hip" type="ball" pos="0 0 0"/>
        <geom pos="0.0695 0.3139 -0.0239" type="mesh" contype="1" conaffinity="1" mesh="R_Hip"/>
        <body name="R_Knee" pos="-0.0383 -0.3825 -0.0089" gravcomp="0">
          <joint name="R_Knee" type="ball" pos="0 0 0"/>
          <geom pos="0.1078 0.6964 -0.015" type="mesh" contype="1" conaffinity="1" mesh="R_Knee"/>
          <body name="R_Ankle" pos="0.0158 -0.3984 -0.0423" gravcomp="0">
            <joint name="R_Ankle" type="ball" pos="0 0 0"/>
            <geom pos="0.092 1.0948 0.0273" type="mesh" contype="1" conaffinity="1" mesh="R_Ankle"/>
            <body name="R_Toe" pos="-0.0254 -0.0482 0.1234" gravcomp="0">
              <joint name="R_Toe" type="ball" pos="0 0 0"/>
              <geom pos="0.1174 1.143 -0.0961" type="mesh" contype="1" conaffinity="1" mesh="R_Toe"/>
            </body>
          </body>
        </body>
      </body>
      <body name="Torso" pos="-0.0025 0.1089 0.0267" gravcomp="0">
        <joint name="Torso" type="ball" pos="0 0 0"/>
        <geom pos="0.0043 0.1144 -0.0015" type="mesh" contype="1" conaffinity="1" mesh="Torso"/>
        <body name="Spine" pos="0.0055 0.1352 0.0011" gravcomp="0">
          <joint name="Spine" type="ball" pos="0 0 0"/>
          <geom pos="-0.0012 -0.0208 -0.0026" type="mesh" contype="1" conaffinity="1" mesh="Spine"/>
          <body name="Chest" pos="0.0014 0.0529 0.0254" gravcomp="0">
            <joint name="Chest" type="ball" pos="0 0 0"/>
            <geom pos="-0.0026 -0.0737 -0.028" type="mesh" contype="1" conaffinity="1" mesh="Chest"/>
            <body name="Neck" pos="-0.0028 0.2139 -0.0428" gravcomp="0">
              <joint name="Neck" type="ball" pos="0 0 0"/>
              <geom pos="0.0002 -0.2876 0.0148" type="mesh" contype="1" conaffinity="1" mesh="Neck"/>
              <body name="Head" pos="0.0052 0.065 0.0513" gravcomp="0">
                <joint name="Head" type="ball" pos="0 0 0"/>
                <geom pos="-0.005 -0.3526 -0.0365" type="mesh" contype="1" conaffinity="1" mesh="Head"/>
              </body>
            </body>
            <body name="L_Thorax" pos="0.0789 0.1218 -0.034" gravcomp="0">
              <joint name="L_Thorax" type="ball" pos="0 0 0"/>
              <geom pos="-0.0815 -0.1955 0.006" type="mesh" contype="1" conaffinity="1" mesh="L_Thorax"/>
              <body name="L_Shoulder" pos="0.0909 0.0305 -0.0089" gravcomp="0">
                <joint name="L_Shoulder" type="ball" pos="0 0 0"/>
                <geom pos="-0.1724 -0.226 0.0149" type="mesh" contype="1" conaffinity="1" mesh="L_Shoulder"/>
                <body name="L_Elbow" pos="0.2596 -0.0128 -0.0275" gravcomp="0">
                  <joint name="L_Elbow" type="ball" pos="0 0 0"/>
                  <geom pos="-0.432 -0.2132 0.0424" type="mesh" contype="1" conaffinity="1" mesh="L_Elbow"/>
                  <body name="L_Wrist" pos="0.2493 0.009 -0.0011" gravcomp="0">
                    <joint name="L_Wrist" type="ball" pos="0 0 0"/>
                    <geom pos="-0.6813 -0.2222 0.0435" type="mesh" contype="1" conaffinity="1" mesh="L_Wrist"/>
<!--                    <body name="L_Hand" pos="0.084 -0.0082 -0.015" gravcomp="0">-->
<!--                      <joint name="L_Hand" type="ball" pos="0 0 0"/>-->
<!--                      <geom pos="-0.7653 -0.214 0.0585" type="mesh" contype="1" conaffinity="1" mesh="L_Hand"/>-->
<!--                    </body>-->
                  </body>
                </body>
              </body>
            </body>
            <body name="R_Thorax" pos="-0.0817 0.1189 -0.0386" gravcomp="0">
              <joint name="R_Thorax" type="ball" pos="0 0 0"/>
              <geom pos="0.0791 -0.1926 0.0106" type="mesh" contype="1" conaffinity="1" mesh="R_Thorax"/>
              <body name="R_Shoulder" pos="-0.0961 0.0325 -0.0091" gravcomp="0">
                <joint name="R_Shoulder" type="ball" pos="0 0 0"/>
                <geom pos="0.1752 -0.2251 0.0197" type="mesh" contype="1" conaffinity="1" mesh="R_Shoulder"/>
                <body name="R_Elbow" pos="-0.2537 -0.0133 -0.0214" gravcomp="0">
                  <joint name="R_Elbow" type="ball" pos="0 0 0"/>
                  <geom pos="0.4289 -0.2118 0.0411" type="mesh" contype="1" conaffinity="1" mesh="R_Elbow"/>
                  <body name="R_Wrist" pos="-0.2553 0.0078 -0.0056" gravcomp="0">
                    <joint name="R_Wrist" type="ball" pos="0 0 0"/>
                    <geom pos="0.6842 -0.2196 0.0467" type="mesh" contype="1" conaffinity="1" mesh="R_Wrist"/>
<!--                    <body name="R_Hand" pos="-0.0846 -0.0062 -0.0103" gravcomp="0">-->
<!--                      <joint name="R_Hand" type="ball" pos="0 0 0"/>-->
<!--                      <geom pos="0.7688 -0.2134 0.057" type="mesh" contype="1" conaffinity="1" mesh="R_Hand"/>-->
<!--                    </body>-->
                  </body>
                </body>
              </body>
            </body>
          </body>
        </body>
      </body>
    </body>
  </worldbody>
  <actuator>
    <general name="Pelvis" joint="Pelvis" actdim="-1"/>
    <general name="L_Hip" joint="L_Hip" actdim="-1"/>
    <general name="R_Hip" joint="R_Hip" actdim="-1"/>
    <general name="Torso" joint="Torso" actdim="-1"/>
    <general name="L_Knee" joint="L_Knee" actdim="-1"/>
    <general name="R_Knee" joint="R_Knee" actdim="-1"/>
    <general name="Spine" joint="Spine" actdim="-1"/>
    <general name="L_Ankle" joint="L_Ankle" actdim="-1"/>
    <general name="R_Ankle" joint="R_Ankle" actdim="-1"/>
    <general name="Chest" joint="Chest" actdim="-1"/>
    <general name="L_Toe" joint="L_Toe" actdim="-1"/>
    <general name="R_Toe" joint="R_Toe" actdim="-1"/>
    <general name="Neck" joint="Neck" actdim="-1"/>
    <general name="L_Thorax" joint="L_Thorax" actdim="-1"/>
    <general name="R_Thorax" joint="R_Thorax" actdim="-1"/>
    <general name="Head" joint="Head" actdim="-1"/>
    <general name="L_Shoulder" joint="L_Shoulder" actdim="-1"/>
    <general name="R_Shoulder" joint="R_Shoulder" actdim="-1"/>
    <general name="L_Elbow" joint="L_Elbow" actdim="-1"/>
    <general name="R_Elbow" joint="R_Elbow" actdim="-1"/>
    <general name="L_Wrist" joint="L_Wrist" actdim="-1"/>
    <general name="R_Wrist" joint="R_Wrist" actdim="-1"/>
<!--    <general name="L_Hand" joint="L_Hand" actdim="-1"/>-->
<!--    <general name="R_Hand" joint="R_Hand" actdim="-1"/>-->
  </actuator>
</mujoco>
